2020-08-16 10:48:20;INFO;User: admin is looking for מגן אחורי,מגן קדמי for vin=CJ500444
2020-08-16 10:48:45;WARNING;cant take screen shot for 7410AR
2020-08-16 10:48:50;WARNING;cant take screen shot for 7401WK
2020-08-16 10:51:34;INFO;User: admin is looking for מגן קדמי,מגן אחורי for vin=CJ500444
2020-08-16 10:55:35;WARNING;cant take screen shot for 7401WK
2020-08-16 10:55:43;WARNING;cant take screen shot for 7410AR
2020-08-16 11:28:50;ERROR;Message: stale element reference: element is not attached to the page document
  (Session info: chrome=84.0.4147.125)
  (Driver info: chromedriver=2.43.600210 (68dcf5eebde37173d4027fa8635e332711d2874a),platform=Windows NT 10.0.19041 x86_64)
Traceback (most recent call last):
  File "C:\Users\roy\PycharmProjects\JSP\WebDriver.py", line 182, in over_every_parts
    part_number = self.copy_part_number(part, car_name)
  File "C:\Users\roy\PycharmProjects\JSP\WebDriver.py", line 109, in copy_part_number
    part_number = self.get_value_from_multi_part_numbers(part)
  File "C:\Users\roy\PycharmProjects\JSP\WebDriver.py", line 105, in get_value_from_multi_part_numbers
    return part_number[0].text
  File "C:\Users\roy\AppData\Local\Programs\Python\Python37\lib\site-packages\selenium\webdriver\remote\webelement.py", line 76, in text
    return self._execute(Command.GET_ELEMENT_TEXT)['value']
  File "C:\Users\roy\AppData\Local\Programs\Python\Python37\lib\site-packages\selenium\webdriver\remote\webelement.py", line 633, in _execute
    return self._parent.execute(command, params)
  File "C:\Users\roy\AppData\Local\Programs\Python\Python37\lib\site-packages\selenium\webdriver\remote\webdriver.py", line 321, in execute
    self.error_handler.check_response(response)
  File "C:\Users\roy\AppData\Local\Programs\Python\Python37\lib\site-packages\selenium\webdriver\remote\errorhandler.py", line 242, in check_response
    raise exception_class(message, screen, stacktrace)
selenium.common.exceptions.StaleElementReferenceException: Message: stale element reference: element is not attached to the page document
  (Session info: chrome=84.0.4147.125)
  (Driver info: chromedriver=2.43.600210 (68dcf5eebde37173d4027fa8635e332711d2874a),platform=Windows NT 10.0.19041 x86_64)

2020-08-16 11:28:50;ERROR;Can't find these parts by sections
Traceback (most recent call last):
  File "C:\Users\roy\PycharmProjects\JSP\WebDriver.py", line 182, in over_every_parts
    part_number = self.copy_part_number(part, car_name)
  File "C:\Users\roy\PycharmProjects\JSP\WebDriver.py", line 109, in copy_part_number
    part_number = self.get_value_from_multi_part_numbers(part)
  File "C:\Users\roy\PycharmProjects\JSP\WebDriver.py", line 105, in get_value_from_multi_part_numbers
    return part_number[0].text
  File "C:\Users\roy\AppData\Local\Programs\Python\Python37\lib\site-packages\selenium\webdriver\remote\webelement.py", line 76, in text
    return self._execute(Command.GET_ELEMENT_TEXT)['value']
  File "C:\Users\roy\AppData\Local\Programs\Python\Python37\lib\site-packages\selenium\webdriver\remote\webelement.py", line 633, in _execute
    return self._parent.execute(command, params)
  File "C:\Users\roy\AppData\Local\Programs\Python\Python37\lib\site-packages\selenium\webdriver\remote\webdriver.py", line 321, in execute
    self.error_handler.check_response(response)
  File "C:\Users\roy\AppData\Local\Programs\Python\Python37\lib\site-packages\selenium\webdriver\remote\errorhandler.py", line 242, in check_response
    raise exception_class(message, screen, stacktrace)
selenium.common.exceptions.StaleElementReferenceException: Message: stale element reference: element is not attached to the page document
  (Session info: chrome=84.0.4147.125)
  (Driver info: chromedriver=2.43.600210 (68dcf5eebde37173d4027fa8635e332711d2874a),platform=Windows NT 10.0.19041 x86_64)

2020-08-16 11:28:56;WARNING;cant take screen shot for 7410AR
2020-08-16 11:39:25;WARNING;cant take screen shot for 7401WK
2020-08-16 11:39:31;WARNING;cant take screen shot for 7410AR
2020-08-16 11:42:44;WARNING;cant take screen shot for 7401WK
2020-08-16 11:42:50;WARNING;cant take screen shot for 7410AR
2020-08-16 16:13:15;WARNING;cant take screen shot for 7401WK
2020-08-16 16:13:25;WARNING;cant take screen shot for 7410AR
2020-09-19 23:24:25;ERROR;User name or password are wrong!
Traceback (most recent call last):
  File "C:/Users/roy/PycharmProjects/JSP/WebApplication.py", line 102, in return_current_driver
    driver._driver.title
NameError: name 'driver' is not defined

During handling of the above exception, another exception occurred:

Traceback (most recent call last):
  File "C:\Users\roy\PycharmProjects\JSP\WebDriver.py", line 37, in login
    self._driver.find_element_by_xpath('//*[@id="userid"]').send_keys(user_name)
  File "C:\Users\roy\AppData\Local\Programs\Python\Python37\lib\site-packages\selenium\webdriver\remote\webdriver.py", line 394, in find_element_by_xpath
    return self.find_element(by=By.XPATH, value=xpath)
  File "C:\Users\roy\AppData\Local\Programs\Python\Python37\lib\site-packages\selenium\webdriver\remote\webdriver.py", line 978, in find_element
    'value': value})['value']
  File "C:\Users\roy\AppData\Local\Programs\Python\Python37\lib\site-packages\selenium\webdriver\remote\webdriver.py", line 321, in execute
    self.error_handler.check_response(response)
  File "C:\Users\roy\AppData\Local\Programs\Python\Python37\lib\site-packages\selenium\webdriver\remote\errorhandler.py", line 242, in check_response
    raise exception_class(message, screen, stacktrace)
selenium.common.exceptions.NoSuchElementException: Message: no such element: Unable to locate element: {"method":"xpath","selector":"//*[@id="userid"]"}
  (Session info: chrome=85.0.4183.102)
  (Driver info: chromedriver=2.43.600210 (68dcf5eebde37173d4027fa8635e332711d2874a),platform=Windows NT 10.0.19041 x86_64)

2020-09-19 23:24:25;ERROR;User name or password are wrong!
2020-09-19 23:24:25;ERROR;init_driver failed in try number 1
2020-09-19 23:24:31;ERROR;User name or password are wrong!
Traceback (most recent call last):
  File "C:/Users/roy/PycharmProjects/JSP/WebApplication.py", line 102, in return_current_driver
    driver._driver.title
NameError: name 'driver' is not defined

During handling of the above exception, another exception occurred:

Traceback (most recent call last):
  File "C:\Users\roy\PycharmProjects\JSP\WebDriver.py", line 37, in login
    self._driver.find_element_by_xpath('//*[@id="userid"]').send_keys(user_name)
  File "C:\Users\roy\AppData\Local\Programs\Python\Python37\lib\site-packages\selenium\webdriver\remote\webdriver.py", line 394, in find_element_by_xpath
    return self.find_element(by=By.XPATH, value=xpath)
  File "C:\Users\roy\AppData\Local\Programs\Python\Python37\lib\site-packages\selenium\webdriver\remote\webdriver.py", line 978, in find_element
    'value': value})['value']
  File "C:\Users\roy\AppData\Local\Programs\Python\Python37\lib\site-packages\selenium\webdriver\remote\webdriver.py", line 321, in execute
    self.error_handler.check_response(response)
  File "C:\Users\roy\AppData\Local\Programs\Python\Python37\lib\site-packages\selenium\webdriver\remote\errorhandler.py", line 242, in check_response
    raise exception_class(message, screen, stacktrace)
selenium.common.exceptions.NoSuchElementException: Message: no such element: Unable to locate element: {"method":"xpath","selector":"//*[@id="userid"]"}
  (Session info: chrome=85.0.4183.102)
  (Driver info: chromedriver=2.43.600210 (68dcf5eebde37173d4027fa8635e332711d2874a),platform=Windows NT 10.0.19041 x86_64)

2020-09-19 23:24:31;ERROR;User name or password are wrong!
2020-09-19 23:24:31;ERROR;init_driver failed in try number 2
2020-09-19 23:25:58;ERROR;User name or password are wrong!
Traceback (most recent call last):
  File "C:/Users/roy/PycharmProjects/JSP/WebApplication.py", line 102, in return_current_driver
    driver._driver.title
NameError: name 'driver' is not defined

During handling of the above exception, another exception occurred:

Traceback (most recent call last):
  File "C:\Users\roy\PycharmProjects\JSP\WebDriver.py", line 37, in login
    self._driver.find_element_by_xpath('//*[@id="userid"]').send_keys(user_name)
  File "C:\Users\roy\AppData\Local\Programs\Python\Python37\lib\site-packages\selenium\webdriver\remote\webdriver.py", line 394, in find_element_by_xpath
    return self.find_element(by=By.XPATH, value=xpath)
  File "C:\Users\roy\AppData\Local\Programs\Python\Python37\lib\site-packages\selenium\webdriver\remote\webdriver.py", line 978, in find_element
    'value': value})['value']
  File "C:\Users\roy\AppData\Local\Programs\Python\Python37\lib\site-packages\selenium\webdriver\remote\webdriver.py", line 321, in execute
    self.error_handler.check_response(response)
  File "C:\Users\roy\AppData\Local\Programs\Python\Python37\lib\site-packages\selenium\webdriver\remote\errorhandler.py", line 242, in check_response
    raise exception_class(message, screen, stacktrace)
selenium.common.exceptions.NoSuchElementException: Message: no such element: Unable to locate element: {"method":"xpath","selector":"//*[@id="userid"]"}
  (Session info: chrome=85.0.4183.102)
  (Driver info: chromedriver=2.43.600210 (68dcf5eebde37173d4027fa8635e332711d2874a),platform=Windows NT 10.0.19041 x86_64)

2020-09-19 23:25:58;ERROR;User name or password are wrong!
2020-09-19 23:25:58;ERROR;init_driver failed in try number 1
2020-09-19 23:26:04;ERROR;User name or password are wrong!
Traceback (most recent call last):
  File "C:/Users/roy/PycharmProjects/JSP/WebApplication.py", line 102, in return_current_driver
    driver._driver.title
NameError: name 'driver' is not defined

During handling of the above exception, another exception occurred:

Traceback (most recent call last):
  File "C:\Users\roy\PycharmProjects\JSP\WebDriver.py", line 37, in login
    self._driver.find_element_by_xpath('//*[@id="userid"]').send_keys(user_name)
  File "C:\Users\roy\AppData\Local\Programs\Python\Python37\lib\site-packages\selenium\webdriver\remote\webdriver.py", line 394, in find_element_by_xpath
    return self.find_element(by=By.XPATH, value=xpath)
  File "C:\Users\roy\AppData\Local\Programs\Python\Python37\lib\site-packages\selenium\webdriver\remote\webdriver.py", line 978, in find_element
    'value': value})['value']
  File "C:\Users\roy\AppData\Local\Programs\Python\Python37\lib\site-packages\selenium\webdriver\remote\webdriver.py", line 321, in execute
    self.error_handler.check_response(response)
  File "C:\Users\roy\AppData\Local\Programs\Python\Python37\lib\site-packages\selenium\webdriver\remote\errorhandler.py", line 242, in check_response
    raise exception_class(message, screen, stacktrace)
selenium.common.exceptions.NoSuchElementException: Message: no such element: Unable to locate element: {"method":"xpath","selector":"//*[@id="userid"]"}
  (Session info: chrome=85.0.4183.102)
  (Driver info: chromedriver=2.43.600210 (68dcf5eebde37173d4027fa8635e332711d2874a),platform=Windows NT 10.0.19041 x86_64)

2020-09-19 23:26:04;ERROR;User name or password are wrong!
2020-09-19 23:26:04;ERROR;init_driver failed in try number 2
2020-09-19 23:28:50;ERROR;User name or password are wrong!
Traceback (most recent call last):
  File "C:/Users/roy/PycharmProjects/JSP/WebApplication.py", line 102, in return_current_driver
    driver._driver.title
NameError: name 'driver' is not defined

During handling of the above exception, another exception occurred:

Traceback (most recent call last):
  File "C:\Users\roy\PycharmProjects\JSP\WebDriver.py", line 37, in login
    self._driver.find_element_by_xpath('//*[@id="userid"]').send_keys(user_name)
  File "C:\Users\roy\AppData\Local\Programs\Python\Python37\lib\site-packages\selenium\webdriver\remote\webdriver.py", line 394, in find_element_by_xpath
    return self.find_element(by=By.XPATH, value=xpath)
  File "C:\Users\roy\AppData\Local\Programs\Python\Python37\lib\site-packages\selenium\webdriver\remote\webdriver.py", line 978, in find_element
    'value': value})['value']
  File "C:\Users\roy\AppData\Local\Programs\Python\Python37\lib\site-packages\selenium\webdriver\remote\webdriver.py", line 321, in execute
    self.error_handler.check_response(response)
  File "C:\Users\roy\AppData\Local\Programs\Python\Python37\lib\site-packages\selenium\webdriver\remote\errorhandler.py", line 242, in check_response
    raise exception_class(message, screen, stacktrace)
selenium.common.exceptions.NoSuchElementException: Message: no such element: Unable to locate element: {"method":"xpath","selector":"//*[@id="userid"]"}
  (Session info: chrome=85.0.4183.102)
  (Driver info: chromedriver=2.43.600210 (68dcf5eebde37173d4027fa8635e332711d2874a),platform=Windows NT 10.0.19041 x86_64)

2020-09-19 23:28:50;ERROR;User name or password are wrong!
2020-09-19 23:28:50;ERROR;init_driver failed in try number 1
2020-09-19 23:28:56;ERROR;User name or password are wrong!
Traceback (most recent call last):
  File "C:/Users/roy/PycharmProjects/JSP/WebApplication.py", line 102, in return_current_driver
    driver._driver.title
NameError: name 'driver' is not defined

During handling of the above exception, another exception occurred:

Traceback (most recent call last):
  File "C:\Users\roy\PycharmProjects\JSP\WebDriver.py", line 37, in login
    self._driver.find_element_by_xpath('//*[@id="userid"]').send_keys(user_name)
  File "C:\Users\roy\AppData\Local\Programs\Python\Python37\lib\site-packages\selenium\webdriver\remote\webdriver.py", line 394, in find_element_by_xpath
    return self.find_element(by=By.XPATH, value=xpath)
  File "C:\Users\roy\AppData\Local\Programs\Python\Python37\lib\site-packages\selenium\webdriver\remote\webdriver.py", line 978, in find_element
    'value': value})['value']
  File "C:\Users\roy\AppData\Local\Programs\Python\Python37\lib\site-packages\selenium\webdriver\remote\webdriver.py", line 321, in execute
    self.error_handler.check_response(response)
  File "C:\Users\roy\AppData\Local\Programs\Python\Python37\lib\site-packages\selenium\webdriver\remote\errorhandler.py", line 242, in check_response
    raise exception_class(message, screen, stacktrace)
selenium.common.exceptions.NoSuchElementException: Message: no such element: Unable to locate element: {"method":"xpath","selector":"//*[@id="userid"]"}
  (Session info: chrome=85.0.4183.102)
  (Driver info: chromedriver=2.43.600210 (68dcf5eebde37173d4027fa8635e332711d2874a),platform=Windows NT 10.0.19041 x86_64)

2020-09-19 23:28:56;ERROR;User name or password are wrong!
2020-09-19 23:28:56;ERROR;init_driver failed in try number 2
2020-09-20 12:10:27;WARNING;cant take screen shot for 7401WK
2020-09-20 12:10:33;WARNING;cant take screen shot for 7410AR
2020-09-20 12:12:38;WARNING;cant take screen shot for 1607397880
2020-09-20 12:12:44;WARNING;cant take screen shot for 1607254580
2020-09-20 12:13:05;WARNING;cant take screen shot for 1607397880
2020-09-20 12:13:11;WARNING;cant take screen shot for 1607254580
2020-09-20 13:45:43;ERROR;Message: session not created
from chrome not reachable
  (Session info: chrome=85.0.4183.102)
  (Driver info: chromedriver=2.43.600210 (68dcf5eebde37173d4027fa8635e332711d2874a),platform=Windows NT 10.0.19041 x86_64)

2020-09-20 13:45:43;ERROR;init_driver failed in try number 1
2020-09-20 13:45:50;ERROR;Message: unknown error: cannot determine loading status
from disconnected: received Inspector.detached event
  (Session info: chrome=85.0.4183.102)
  (Driver info: chromedriver=2.43.600210 (68dcf5eebde37173d4027fa8635e332711d2874a),platform=Windows NT 10.0.19041 x86_64)

2020-09-20 13:45:50;ERROR;init_driver failed in try number 2
2020-09-20 13:48:08;ERROR;Message: chrome not reachable
  (Session info: chrome=85.0.4183.102)
  (Driver info: chromedriver=2.43.600210 (68dcf5eebde37173d4027fa8635e332711d2874a),platform=Windows NT 10.0.19041 x86_64)

2020-09-20 13:48:08;ERROR;init_driver failed in try number 1
2020-09-20 13:48:25;ERROR;Message: session not created
from chrome not reachable
  (Session info: chrome=85.0.4183.102)
  (Driver info: chromedriver=2.43.600210 (68dcf5eebde37173d4027fa8635e332711d2874a),platform=Windows NT 10.0.19041 x86_64)

2020-09-20 13:48:25;ERROR;init_driver failed in try number 2
2020-09-20 15:32:24;WARNING;cant take screen shot for 1444VX
